<?xml version="1.0" encoding="utf-8"?>
<!-- This URDF was automatically created by SolidWorks to URDF Exporter! Originally created by Stephen Brawner (brawner@gmail.com) 
     Commit Version: 1.6.0-4-g7f85cfe  Build Version: 1.6.7995.38578
     For more information, please see http://wiki.ros.org/sw_urdf_exporter -->
<robot xmlns:xacro="http://ros.org/wiki/xacro" name="dashgo">
  <link
    name="Base">
    <inertial>
      <origin
        xyz="7.28752940389763E-05 0.0569098315439798 0.259207232289335"
        rpy="0 0 0" />
      <mass
        value="5.92220977742572" />
      <inertia
        ixx="0.134189556605473"
        ixy="-2.49642917566465E-05"
        ixz="7.32459015245289E-10"
        iyy="0.135866070097009"
        iyz="0.000122787889238699"
        izz="0.0791062934791391" />
    </inertial>
    <visual>
      <origin
        xyz="0 0 0"
        rpy="0 0 0" />
      <geometry>
        <mesh
          filename="package://robot_description/meshes/Dashgo/Base.STL" />
      </geometry>
      <material
        name="">
        <color
          rgba="0.792156862745098 0.819607843137255 0.933333333333333 1" />
      </material>
    </visual>
    <collision>
      <origin
        xyz="0 0 0"
        rpy="0 0 0" />
      <geometry>
        <mesh
          filename="package://robot_description/meshes/Dashgo/Base.STL" />
      </geometry>
    </collision>
  </link>
  <link
    name="Llanta1">
    <inertial>
      <origin
        xyz="5.39845945723982E-15 1.04291575375726E-14 0.019999999999994"
        rpy="0 0 0" />
      <mass
        value="0.528918539158378" />
      <inertia
        ixx="0.000631308353030454"
        ixy="6.14301607074545E-41"
        ixz="1.72050413075699E-18"
        iyy="0.000631308353030454"
        iyz="-1.33885585873066E-36"
        izz="0.00112157176228534" />
    </inertial>
    <visual>
      <origin
        xyz="0 0 0"
        rpy="0 0 0" />
      <geometry>
        <mesh
          filename="package://robot_description/meshes/Dashgo/Llanta1.STL" />
      </geometry>
      <material
        name="">
        <color
          rgba="0.792156862745098 0.819607843137255 0.933333333333333 1" />
      </material>
    </visual>
    <collision>
      <origin
        xyz="0 0 0"
        rpy="0 0 0" />
      <geometry>
        <mesh
          filename="package://robot_description/meshes/Dashgo/Llanta1.STL" />
      </geometry>
    </collision>
  </link>
  <joint
    name="Cont1_1Llanta"
    type="continuous">
    <origin
      xyz="0.146 0.1155 0.0375"
      rpy="1.5708 0 1.5708" />
    <parent
      link="Base" />
    <child
      link="Llanta1" />
    <axis
      xyz="0 0 1" />
  </joint>
  <link
    name="Llanta2">
    <inertial>
      <origin
        xyz="-1.38777878078145E-17 -1.11022302462516E-16 -0.02"
        rpy="0 0 0" />
      <mass
        value="0.528918539158378" />
      <inertia
        ixx="0.000631308353030454"
        ixy="-8.470329472543E-22"
        ixz="-9.10263751530836E-20"
        iyy="0.000631308353030454"
        iyz="4.50857846912387E-20"
        izz="0.00112157176228534" />
    </inertial>
    <visual>
      <origin
        xyz="0 0 0"
        rpy="0 0 0" />
      <geometry>
        <mesh
          filename="package://robot_description/meshes/Dashgo/Llanta2.STL" />
      </geometry>
      <material
        name="">
        <color
          rgba="0.792156862745098 0.819607843137255 0.933333333333333 1" />
      </material>
    </visual>
    <collision>
      <origin
        xyz="0 0 0"
        rpy="0 0 0" />
      <geometry>
        <mesh
          filename="package://robot_description/meshes/Dashgo/Llanta2.STL" />
      </geometry>
    </collision>
  </link>
  <joint
    name="Cont1_2Llanta"
    type="continuous">
    <origin
      xyz="-0.146 0.1155 0.0375"
      rpy="1.5708 0.020949 1.5708" />
    <parent
      link="Base" />
    <child
      link="Llanta2" />
    <axis
      xyz="0 0 1" />
  </joint>
  <link
    name="Loca1">
    <inertial>
      <origin
        xyz="0 0.0345546529721542 1.38777878078145E-17"
        rpy="0 0 0" />
      <mass
        value="0.0167352759899297" />
      <inertia
        ixx="7.54150196205056E-06"
        ixy="1.39395083716622E-21"
        ixz="-8.27180612553027E-22"
        iyy="5.85653067123054E-06"
        iyz="-1.76985419744977E-21"
        izz="7.09027556219276E-06" />
    </inertial>
    <visual>
      <origin
        xyz="0 0 0"
        rpy="0 0 0" />
      <geometry>
        <mesh
          filename="package://robot_description/meshes/Dashgo/Loca1.STL" />
      </geometry>
      <material
        name="">
        <color
          rgba="0.792156862745098 0.819607843137255 0.933333333333333 1" />
      </material>
    </visual>
    <collision>
      <origin
        xyz="0 0 0"
        rpy="0 0 0" />
      <geometry>
        <mesh
          filename="package://robot_description/meshes/Dashgo/Loca1.STL" />
      </geometry>
    </collision>
  </link>
  <joint
    name="Cont2_1Loca"
    type="continuous">
    <origin
      xyz="-0.09 -0.0720000000000001 0"
      rpy="1.5707963267949 0 0" />
    <parent
      link="Base" />
    <child
      link="Loca1" />
    <axis
      xyz="0 1 0" />
  </joint>
  <link
    name="LlantaLoca1">
    <inertial>
      <origin
        xyz="-2.77555756156289E-17 -0.00741632050454702 0"
        rpy="0 0 0" />
      <mass
        value="0.0694291976443344" />
      <inertia
        ixx="3.17985725211052E-05"
        ixy="-5.2134949516848E-38"
        ixz="0"
        iyy="1.95153903045283E-05"
        iyz="7.67877008722871E-41"
        izz="1.95153903045283E-05" />
    </inertial>
    <visual>
      <origin
        xyz="0 0 0"
        rpy="0 0 0" />
      <geometry>
        <mesh
          filename="package://robot_description/meshes/Dashgo/LlantaLoca1.STL" />
      </geometry>
      <material
        name="">
        <color
          rgba="0.792156862745098 0.819607843137255 0.933333333333333 1" />
      </material>
    </visual>
    <collision>
      <origin
        xyz="0 0 0"
        rpy="0 0 0" />
      <geometry>
        <mesh
          filename="package://robot_description/meshes/Dashgo/LlantaLoca1.STL" />
      </geometry>
    </collision>
  </link>
  <joint
    name="Cont2_2Llanta"
    type="continuous">
    <origin
      xyz="0 0.01 0"
      rpy="0 0 0" />
    <parent
      link="Loca1" />
    <child
      link="LlantaLoca1" />
    <axis
      xyz="1 0 0" />
  </joint>
  <link
    name="Loca2">
    <inertial>
      <origin
        xyz="-4.16333634234434E-17 0.0345546529721542 5.55111512312578E-17"
        rpy="0 0 0" />
      <mass
        value="0.0167352759899297" />
      <inertia
        ixx="7.54150196205055E-06"
        ixy="3.0363079599354E-21"
        ixz="2.64697796016969E-22"
        iyy="5.85653067123052E-06"
        iyz="4.10688840129326E-22"
        izz="7.09027556219275E-06" />
    </inertial>
    <visual>
      <origin
        xyz="0 0 0"
        rpy="0 0 0" />
      <geometry>
        <mesh
          filename="package://robot_description/meshes/Dashgo/Loca2.STL" />
      </geometry>
      <material
        name="">
        <color
          rgba="0.792156862745098 0.819607843137255 0.933333333333333 1" />
      </material>
    </visual>
    <collision>
      <origin
        xyz="0 0 0"
        rpy="0 0 0" />
      <geometry>
        <mesh
          filename="package://robot_description/meshes/Dashgo/Loca2.STL" />
      </geometry>
    </collision>
  </link>
  <joint
    name="Cont3_1Loca"
    type="continuous">
    <origin
      xyz="0.09 -0.072 0"
      rpy="1.5707963267949 0 0.132004559319761" />
    <parent
      link="Base" />
    <child
      link="Loca2" />
    <axis
      xyz="0 1 0" />
  </joint>
  <link
    name="LlantaLoca2">
    <inertial>
      <origin
        xyz="-1.72084568816899E-15 -0.00469061857919632 -0.00574455456677565"
        rpy="0 0 0" />
      <mass
        value="0.0694291976443344" />
      <inertia
        ixx="3.17985725211052E-05"
        ixy="1.6940658945086E-21"
        ixz="-2.22346148654254E-21"
        iyy="1.95153903045283E-05"
        iyz="2.5410988417629E-21"
        izz="1.95153903045283E-05" />
    </inertial>
    <visual>
      <origin
        xyz="0 0 0"
        rpy="0 0 0" />
      <geometry>
        <mesh
          filename="package://robot_description/meshes/Dashgo/LlantaLoca2.STL" />
      </geometry>
      <material
        name="">
        <color
          rgba="0.792156862745098 0.819607843137255 0.933333333333333 1" />
      </material>
    </visual>
    <collision>
      <origin
        xyz="0 0 0"
        rpy="0 0 0" />
      <geometry>
        <mesh
          filename="package://robot_description/meshes/Dashgo/LlantaLoca2.STL" />
      </geometry>
    </collision>
  </link>
  <joint
    name="Cont3_2Llanta"
    type="continuous">
    <origin
      xyz="0 0.01 0"
      rpy="-0.886055251315474 0 0" />
    <parent
      link="Loca2" />
    <child
      link="LlantaLoca2" />
    <axis
      xyz="1 0 0" />
  </joint>
  <link
    name="Lidar">
    <inertial>
      <origin
        xyz="-9.49517221724887E-50 0.0125 -1.38777878078145E-17"
        rpy="0 0 0" />
      <mass
        value="0.0962112750161874" />
      <inertia
        ixx="3.44757068808005E-05"
        ixy="8.13422838622583E-38"
        ixz="1.3254524700622E-52"
        iyy="5.89294059474148E-05"
        iyz="-6.00991536754997E-37"
        izz="3.44757068808005E-05" />
    </inertial>
    <visual>
      <origin
        xyz="0 0 0"
        rpy="0 0 0" />
      <geometry>
        <mesh
          filename="package://robot_description/meshes/Dashgo/Lidar.STL" />
      </geometry>
      <material
        name="">
        <color
          rgba="0.792156862745098 0.819607843137255 0.933333333333333 1" />
      </material>
    </visual>
    <collision>
      <origin
        xyz="0 0 0"
        rpy="0 0 0" />
      <geometry>
        <mesh
          filename="package://robot_description/meshes/Dashgo/Lidar.STL" />
      </geometry>
    </collision>
  </link>
  <joint
    name="Cont4_1Lidar"
    type="fixed">
    <origin
      xyz="0 -0.11 0.12"
      rpy="1.5707963267949 0 0" />
    <parent
      link="Base" />
    <child
      link="Lidar" />
  </joint>
  <link
    name="RevCam1">
    <inertial>
      <origin
        xyz="-0.00218640113558179 0.0383778465870386 -0.00515828443968225"
        rpy="0 0 0" />
      <mass
        value="0.0807173201754209" />
      <inertia
        ixx="2.37796512993044E-05"
        ixy="8.55530391588438E-07"
        ixz="-2.49698267928064E-07"
        iyy="1.83589770932125E-05"
        iyz="-4.19202714077008E-06"
        izz="2.27836705307719E-05" />
    </inertial>
    <visual>
      <origin
        xyz="0 0 0"
        rpy="0 0 0" />
      <geometry>
        <mesh
          filename="package://robot_description/meshes/Dashgo/RevCam1.STL" />
      </geometry>
      <material
        name="">
        <color
          rgba="0.792156862745098 0.819607843137255 0.933333333333333 1" />
      </material>
    </visual>
    <collision>
      <origin
        xyz="0 0 0"
        rpy="0 0 0" />
      <geometry>
        <mesh
          filename="package://robot_description/meshes/Dashgo/RevCam1.STL" />
      </geometry>
    </collision>
  </link>
  <joint
    name="Rev1Cam"
    type="revolute">
    <origin
      xyz="0.001 0.0505 1.745"
      rpy="1.5708 0 0.034703" />
    <parent
      link="Base" />
    <child
      link="RevCam1" />
    <axis
      xyz="0 1 0" />
    <limit
      lower="-0.5236"
      upper="0.5236"
      effort="0"
      velocity="0" />
  </joint>
  <link
    name="RevCam2">
    <inertial>
      <origin
        xyz="-0.0039179304343604 -0.0102932368661917 0.0320850186207662"
        rpy="0 0 0" />
      <mass
        value="0.0649807233686397" />
      <inertia
        ixx="2.60101323603901E-05"
        ixy="-1.98669220487655E-07"
        ixz="-5.07308429498082E-06"
        iyy="4.1839084740969E-05"
        iyz="3.16753039765726E-07"
        izz="3.84670102617887E-05" />
    </inertial>
    <visual>
      <origin
        xyz="0 0 0"
        rpy="0 0 0" />
      <geometry>
        <mesh
          filename="package://robot_description/meshes/Dashgo/RevCam2.STL" />
      </geometry>
      <material
        name="">
        <color
          rgba="0.792156862745098 0.819607843137255 0.933333333333333 1" />
      </material>
    </visual>
    <collision>
      <origin
        xyz="0 0 0"
        rpy="0 0 0" />
      <geometry>
        <mesh
          filename="package://robot_description/meshes/Dashgo/RevCam2.STL" />
      </geometry>
    </collision>
  </link>
  <joint
    name="Rev2Cam"
    type="revolute">
    <origin
      xyz="0 0.05 0"
      rpy="-0.1212 -0.00097408 -0.016054" />
    <parent
      link="RevCam1" />
    <child
      link="RevCam2" />
    <axis
      xyz="0.9913 0 0.13162" />
    <limit
      lower="-0.5236"
      upper="0.5236"
      effort="0"
      velocity="0" />
  </joint>
  <link
    name="Cam">
    <inertial>
      <origin
        xyz="2.70839394232334E-06 0.0154840832193527 0.0423792552563695"
        rpy="0 0 0" />
      <mass
        value="0.152258268041012" />
      <inertia
        ixx="2.28182703915153E-05"
        ixy="-2.56260859534036E-09"
        ixz="-6.38822957916651E-09"
        iyy="0.000372324879577431"
        iyz="-3.15065570917248E-08"
        izz="0.000374741837893712" />
    </inertial>
    <visual>
      <origin
        xyz="0 0 0"
        rpy="0 0 0" />
      <geometry>
        <mesh
          filename="package://robot_description/meshes/Dashgo/Cam.STL" />
      </geometry>
      <material
        name="">
        <color
          rgba="0.176470588235294 0.176470588235294 0.176470588235294 1" />
      </material>
    </visual>
    <collision>
      <origin
        xyz="0 0 0"
        rpy="0 0 0" />
      <geometry>
        <mesh
          filename="package://robot_description/meshes/Dashgo/Cam.STL" />
      </geometry>
    </collision>
  </link>
  <joint
    name="Fix1Cam"
    type="fixed">
    <origin
      xyz="-0.0032151 -0.053982 0.030073"
      rpy="1.4794 0.13201 3.1416" />
    <parent
      link="RevCam2" />
    <child
      link="Cam" />
    <axis
      xyz="0 0 0" />
  </joint>
  <link
    name="BaseBrazo">
    <inertial>
      <origin
        xyz="-3.80554962542412E-17 -6.93889390390723E-17 -4.9999999999939E-05"
        rpy="0 0 0" />
      <mass
        value="0.00121022002997899" />
      <inertia
        ixx="1.17272637070328E-06"
        ixy="2.74649812761777E-23"
        ixz="-1.57772181044193E-28"
        iyy="1.17272637070328E-06"
        iyz="-6.31088724176813E-28"
        izz="2.34545072437318E-06" />
    </inertial>
    <visual>
      <origin
        xyz="0 0 0"
        rpy="0 0 0" />
      <geometry>
        <mesh
          filename="package://robot_description/meshes/Dashgo/BaseBrazo.STL" />
      </geometry>
      <material
        name="">
        <color
          rgba="0.792156862745098 0.819607843137255 0.933333333333333 1" />
      </material>
    </visual>
    <collision>
      <origin
        xyz="0 0 0"
        rpy="0 0 0" />
      <geometry>
        <mesh
          filename="package://robot_description/meshes/Dashgo/BaseBrazo.STL" />
      </geometry>
    </collision>
  </link>
  <joint
    name="Fix6Bra"
    type="fixed">
    <origin
      xyz="0.0005 0.043 0.4581"
      rpy="0 0 0" />
    <parent
      link="Base" />
    <child
      link="BaseBrazo" />
    <axis
      xyz="0 0 0" />
  </joint>



  <!-- XARM -->
  <xacro:arg name="prefix" default=""/>
  <xacro:arg name="ros_namespace" default="xarm"/>
  <xacro:arg name="limited" default="false"/>
  <xacro:arg name="effort_control" default="false"/>
  <xacro:arg name="velocity_control" default="false"/>

  <xacro:arg name="add_other_geometry" default="false"/>
  <xacro:arg name="geometry_type" default="box"/>
  <xacro:arg name="geometry_mass" default="0.1"/>
  <xacro:arg name="geometry_height" default="0.1"/>
  <xacro:arg name="geometry_radius" default="0.1"/>
  <xacro:arg name="geometry_length" default="0.1"/>
  <xacro:arg name="geometry_width" default="0.1"/>
  <xacro:arg name="geometry_mesh_filename" default=""/>
  <xacro:arg name="geometry_mesh_origin_xyz" default="0 0 0"/>
  <xacro:arg name="geometry_mesh_origin_rpy" default="0 0 0"/>
  <xacro:arg name="geometry_mesh_tcp_xyz" default="0 0 0"/>
  <xacro:arg name="geometry_mesh_tcp_rpy" default="0 0 0"/>

  <xacro:arg name="add_realsense_d435i" default="false"/>

  <!-- load xarm5 robot -->
  <xacro:include filename="$(find xarm_description)/urdf/xarm5_robot_macro.xacro" />
  <xacro:xarm5_robot prefix="$(arg prefix)" namespace="$(arg ros_namespace)" limited="$(arg limited)" 
    effort_control="$(arg effort_control)" velocity_control="$(arg velocity_control)"
    rs_d435i="$(arg add_realsense_d435i)"
    attach_to="BaseBrazo"
    add_other_geometry="$(arg add_other_geometry)" 
    geometry_type="$(arg geometry_type)" geometry_mass="$(arg geometry_mass)"
    geometry_height="$(arg geometry_height)" geometry_radius="$(arg geometry_radius)"
    geometry_length="$(arg geometry_length)" geometry_width="$(arg geometry_width)"
    geometry_mesh_filename="$(arg geometry_mesh_filename)"
    geometry_mesh_origin_xyz="$(arg geometry_mesh_origin_xyz)" geometry_mesh_origin_rpy="$(arg geometry_mesh_origin_rpy)"
    geometry_mesh_tcp_xyz="$(arg geometry_mesh_tcp_xyz)" geometry_mesh_tcp_rpy="$(arg geometry_mesh_tcp_rpy)" />

  <!-- load gripper -->
  <xacro:include filename="$(find robot_description)/urdf/gripper/gripper.urdf.xacro" />
  <xacro:load_gripper attach_to="$(arg prefix)link_eef" xyz="0 0 0.003" rpy="0 0 0" />

</robot>