<?xml version="1.0" encoding="utf-8"?>

<robot name="robot_description" 
  xmlns:xacro="http://www.ros.org/wiki/xacro">

  <xacro:include filename="$(find robot_description)/urdf/materials.xacro" />
  <xacro:include filename="$(find robot_description)/urdf/robot.gazebo.xacro" />

  <virtual_joint name="world_joint" type="planar" parent_frame="odom" child_link="base_footprint"/>

  <link name="base_footprint"></link> 

  <!-- Base -->
  <link name="base_link">
    <inertial>
      <origin
        xyz="-0.140101678990613 0.00114478625174914 0.287628607282214"
        rpy="0 0 0" />
      <mass
        value="18.1215133555874" />
      <inertia
        ixx="0.749373660807314"
        ixy="-2.04114489679086E-05"
        ixz="0.0287031101977871"
        iyy="0.757729413836533"
        iyz="-2.12902753512747E-05"
        izz="0.727122404257033" />
    </inertial>
    <visual>
      <origin
        xyz="0 0 0"
        rpy="0 0 0" />
      <geometry>
        <mesh
          filename="package://robot_description/meshes/base_link.STL" />
      </geometry>
      <material
        name="">
        <color
          rgba="0.792156862745098 0.819607843137255 0.933333333333333 1" />
      </material>
    </visual>
    <collision>
      <origin
        xyz="0 0 0"
        rpy="0 0 0" />
      <geometry>
        <mesh
          filename="package://robot_description/meshes/base_link.STL" />
      </geometry>
    </collision>
  </link>
  <joint name="base_joint" type="fixed">
    <origin xyz="0 0 0" rpy="0 0 0"/>
    <parent link="base_footprint"/>
    <child link="base_link"/>
  </joint>

  <!-- Wheel 1 -->
  <link name="R1">
    <inertial>
      <origin
        xyz="3.23195320450775E-07 -0.0179507439124115 1.34412548334628E-07"
        rpy="0 0 0" />
      <mass
        value="0.27570630673027" />
      <inertia
        ixx="6.88913760503531E-05"
        ixy="-9.99707194725952E-11"
        ixz="2.32024543753798E-10"
        iyy="9.7675702655705E-05"
        iyz="2.38192945242156E-10"
        izz="6.88909173459932E-05" />
    </inertial>
    <visual>
      <origin
        xyz="0 0 0"
        rpy="0 0 0" />
      <geometry>
        <mesh
          filename="package://robot_description/meshes/R1.STL" />
      </geometry>
      <material
        name="">
        <color
          rgba="1 1 1 1" />
      </material>
    </visual>
    <collision>
      <origin
        xyz="0 0 0"
        rpy="0 0 0" />
      <geometry>
        <mesh
          filename="package://robot_description/meshes/R1.STL" />
      </geometry>
    </collision>
  </link>
  <joint name="Chasis-R1" type="continuous">
    <origin
      xyz="0.13960999018429 -0.224000012165135 -0.0268998000000014"
      rpy="0 0 0" />
    <parent
      link="base_link" />
    <child
      link="R1" />
    <axis
      xyz="0 1 0" />
  </joint>

  <!-- Wheel 2 -->
  <link name="R2">
    <inertial>
      <origin
        xyz="3.32396812519065E-07 0.0179292857255078 1.09213569882138E-07"
        rpy="0 0 0" />
      <mass
        value="0.275706306313456" />
      <inertia
        ixx="6.88914080188531E-05"
        ixy="-8.21254945713304E-11"
        ixz="1.95157168736736E-10"
        iyy="9.76757022851765E-05"
        iyz="2.44874061876534E-10"
        izz="6.88908849846178E-05" />
    </inertial>
    <visual>
      <origin
        xyz="0 0 0"
        rpy="0 0 0" />
      <geometry>
        <mesh
          filename="package://robot_description/meshes/R2.STL" />
      </geometry>
      <material
        name="">
        <color
          rgba="1 1 1 1" />
      </material>
    </visual>
    <collision>
      <origin
        xyz="0 0 0"
        rpy="0 0 0" />
      <geometry>
        <mesh
          filename="package://robot_description/meshes/R2.STL" />
      </geometry>
    </collision>
  </link>
  <joint name="Chasis-R2" type="continuous">
    <origin
      xyz="0.13960999018429 0.223999987834865 -0.0268998000000016"
      rpy="0 0 0" />
    <parent
      link="base_link" />
    <child
      link="R2" />
    <axis
      xyz="0 1 0" />
  </joint>

  <!-- Wheel 3 -->
  <link name="R3">
    <inertial>
      <origin
        xyz="3.3240531571721E-07 -0.0179507439283899 1.09240773635277E-07"
        rpy="0 0 0" />
      <mass
        value="0.275706305841014" />
      <inertia
        ixx="6.88914080095044E-05"
        ixy="-8.20813841371881E-11"
        ixz="1.95067792411591E-10"
        iyy="9.76757020468613E-05"
        iyz="2.44897502150705E-10"
        izz="6.88908846889313E-05" />
    </inertial>
    <visual>
      <origin
        xyz="0 0 0"
        rpy="0 0 0" />
      <geometry>
        <mesh
          filename="package://robot_description/meshes/R3.STL" />
      </geometry>
      <material
        name="">
        <color
          rgba="1 1 1 1" />
      </material>
    </visual>
    <collision>
      <origin
        xyz="0 0 0"
        rpy="0 0 0" />
      <geometry>
        <mesh
          filename="package://robot_description/meshes/R3.STL" />
      </geometry>
    </collision>
  </link>
  <joint name="Chasis-R3" type="continuous">
    <origin
      xyz="-0.29339000981571 -0.224000012165135 -0.0263997999996424"
      rpy="0 0 0" />
    <parent
      link="base_link" />
    <child
      link="R3" />
    <axis
      xyz="0 1 0" />
  </joint>

  <!-- Wheel 4 -->
  <link name="R4">
    <inertial>
      <origin
        xyz="3.32392385726799E-07 0.017929285725242 1.09201910493406E-07"
        rpy="0 0 0" />
      <mass
        value="0.275706305793894" />
      <inertia
        ixx="6.88914078143537E-05"
        ixy="-8.21406947723185E-11"
        ixz="1.95123343999065E-10"
        iyy="9.76757019588434E-05"
        iyz="2.44857261652816E-10"
        izz="6.88908847877444E-05" />
    </inertial>
    <visual>
      <origin
        xyz="0 0 0"
        rpy="0 0 0" />
      <geometry>
        <mesh
          filename="package://robot_description/meshes/R4.STL" />
      </geometry>
      <material
        name="">
        <color
          rgba="1 1 1 1" />
      </material>
    </visual>
    <collision>
      <origin
        xyz="0 0 0"
        rpy="0 0 0" />
      <geometry>
        <mesh
          filename="package://robot_description/meshes/R4.STL" />
      </geometry>
    </collision>
  </link>
  <joint name="Chasis-R4" type="continuous">
    <origin
      xyz="-0.29339000981571 0.223999987834865 -0.0268998000000015"
      rpy="0 0 0" />
    <parent
      link="base_link" />
    <child
      link="R4" />
    <axis
      xyz="0 1 0" />
  </joint>

  <!-- Elevator -->
  <link name="Elevador">
    <inertial>
      <origin
        xyz="0.0256407575110341 0.00951016603506605 0.836794245964807"
        rpy="0 0 0" />
      <mass
        value="2.29765936695568" />
      <inertia
        ixx="0.125843979664499"
        ixy="-0.00024645090309376"
        ixz="7.99558557981761E-06"
        iyy="0.126438488389742"
        iyz="2.81429202947702E-06"
        izz="0.00295411777217587" />
    </inertial>
    <visual>
      <origin
        xyz="0 0 0"
        rpy="0 0 0" />
      <geometry>
        <mesh
          filename="package://robot_description/meshes/Elevador.STL" />
      </geometry>
      <material
        name="">
        <color
          rgba="0.792156862745098 0.819607843137255 0.933333333333333 1" />
      </material>
    </visual>
    <collision>
      <origin
        xyz="0 0 0"
        rpy="0 0 0" />
      <geometry>
        <mesh
          filename="package://robot_description/meshes/Elevador.STL" />
      </geometry>
    </collision>
  </link>
  <joint name="Chasis-Elevador" type="revolute">
    <origin
      xyz="0 0 -0.0462248000000028"
      rpy="0 0 0" />
    <parent
      link="base_link" />
    <child
      link="Elevador" />
    <axis
      xyz="0 0 1" />
    <limit
      lower="0"
      upper="0"
      effort="0"
      velocity="0" />
  </joint>

  <!-- Arm -->
  <link name="Brazo_1">
    <inertial>
      <origin
        xyz="0.0759877131609833 0.027953575150604 0.0262647126343514"
        rpy="0 0 0" />
      <mass
        value="0.773990320286721" />
      <inertia
        ixx="0.000777921915114249"
        ixy="-0.000249211880454501"
        ixz="7.9321129777271E-06"
        iyy="0.00136773587721977"
        iyz="2.67772483004737E-06"
        izz="0.00197079000077455" />
    </inertial>
    <visual>
      <origin
        xyz="0 0 0"
        rpy="0 0 0" />
      <geometry>
        <mesh
          filename="package://robot_description/meshes/Brazo_1.STL" />
      </geometry>
      <material
        name="">
        <color
          rgba="0.792156862745098 0.819607843137255 0.933333333333333 1" />
      </material>
    </visual>
    <collision>
      <origin
        xyz="0 0 0"
        rpy="0 0 0" />
      <geometry>
        <mesh
          filename="package://robot_description/meshes/Brazo_1.STL" />
      </geometry>
    </collision>
  </link>
  <joint name="Elevador-Brazo_1" type="prismatic">
    <origin
      xyz="0 0 0.614229577737656"
      rpy="0 0 0" />
    <parent
      link="Elevador" />
    <child
      link="Brazo_1" />
    <axis
      xyz="0 0 -1" />
    <limit
      lower="0"
      upper="0"
      effort="0"
      velocity="0" />
  </joint>
  <link name="Brazo_2">
    <inertial>
      <origin
        xyz="0.0649979523199693 -0.0804644889479631 -0.0374323913726272"
        rpy="0 0 0" />
      <mass
        value="0.437735318876537" />
      <inertia
        ixx="0.000607820226495373"
        ixy="0.000430163763985843"
        ixz="-1.81605266791317E-06"
        iyy="0.000700121702994888"
        iyz="1.62843527970453E-06"
        izz="0.00127483380576478" />
    </inertial>
    <visual>
      <origin
        xyz="0 0 0"
        rpy="0 0 0" />
      <geometry>
        <mesh
          filename="package://robot_description/meshes/Brazo_2.STL" />
      </geometry>
      <material
        name="">
        <color
          rgba="0.792156862745098 0.819607843137255 0.933333333333333 1" />
      </material>
    </visual>
    <collision>
      <origin
        xyz="0 0 0"
        rpy="0 0 0" />
      <geometry>
        <mesh
          filename="package://robot_description/meshes/Brazo_2.STL" />
      </geometry>
    </collision>
  </link>
  <joint name="Elevador-Brazo_2" type="revolute">
    <origin
      xyz="0.199881404444355 0.12095830267619 0.00474999999999426"
      rpy="0 0 0" />
    <parent
      link="Brazo_1" />
    <child
      link="Brazo_2" />
    <axis
      xyz="0 0 1" />
    <limit
      lower="0"
      upper="0"
      effort="0"
      velocity="0" />
  </joint>

  <!-- Gripper -->
  <link name="Pinza">
    <inertial>
      <origin
        xyz="0.00822789096267251 -0.160174627601703 -0.0523447920814668"
        rpy="0 0 0" />
      <mass
        value="0.378776731215642" />
      <inertia
        ixx="0.000195731499797995"
        ixy="-5.30850733973627E-06"
        ixz="8.11309040685371E-06"
        iyy="0.000174638445386028"
        iyz="3.53105582147945E-06"
        izz="0.000280838631677078" />
    </inertial>
    <visual>
      <origin
        xyz="0 0 0"
        rpy="0 0 0" />
      <geometry>
        <mesh
          filename="package://robot_description/meshes/Pinza.STL" />
      </geometry>
      <material
        name="">
        <color
          rgba="0.792156862745098 0.819607843137255 0.933333333333333 1" />
      </material>
    </visual>
    <collision>
      <origin
        xyz="0 0 0"
        rpy="0 0 0" />
      <geometry>
        <mesh
          filename="package://robot_description/meshes/Pinza.STL" />
      </geometry>
    </collision>
  </link>
  <joint name="Brazo_2-Pinza" type="revolute">
    <origin
      xyz="0.132103898911925 0.0368532399958369 -0.0561933909573693"
      rpy="0 0 0" />
    <parent
      link="Brazo_2" />
    <child
      link="Pinza" />
    <axis
      xyz="0 0 1" />
    <limit
      lower="0"
      upper="0"
      effort="0"
      velocity="0" />
  </joint>
  <link name="Garra_D">
    <inertial>
      <origin
        xyz="0.0460540376842404 -0.141548931512324 -0.0433793457424966"
        rpy="0 0 0" />
      <mass
        value="0.0862122663862086" />
      <inertia
        ixx="5.18920653975593E-05"
        ixy="-4.52035584941934E-05"
        ixz="-1.64203668115444E-06"
        iyy="0.00011331665564641"
        iyz="-7.60067376670158E-07"
        izz="0.000130229108633702" />
    </inertial>
    <visual>
      <origin
        xyz="0 0 0"
        rpy="0 0 0" />
      <geometry>
        <mesh
          filename="package://robot_description/meshes/Garra_D.STL" />
      </geometry>
      <material
        name="">
        <color
          rgba="0.792156862745098 0.819607843137255 0.933333333333333 1" />
      </material>
    </visual>
    <collision>
      <origin
        xyz="0 0 0"
        rpy="0 0 0" />
      <geometry>
        <mesh
          filename="package://robot_description/meshes/Garra_D.STL" />
      </geometry>
    </collision>
  </link>
  <joint name="Pinza-Garra_D" type="revolute">
    <origin
      xyz="0.0775308919720135 0 -0.0115566090426307"
      rpy="0 0 0" />
    <parent
      link="Pinza" />
    <child
      link="Garra_D" />
    <axis
      xyz="0 0 1" />
    <limit
      lower="0"
      upper="0.61087"
      effort="0"
      velocity="0" />
  </joint>
  <link name="Garra_I">
    <inertial>
      <origin
        xyz="0.0442330222941579 -0.138024523633636 -0.0433792120867414"
        rpy="0 0 0" />
      <mass
        value="0.0862121352254107" />
      <inertia
        ixx="5.00841677058406E-05"
        ixy="-4.39207489780319E-05"
        ixz="-1.57017913968264E-06"
        iyy="0.000115123380941554"
        iyz="-8.99780118632641E-07"
        izz="0.000130227952992073" />
    </inertial>
    <visual>
      <origin
        xyz="0 0 0"
        rpy="0 0 0" />
      <geometry>
        <mesh
          filename="package://robot_description/meshes/Garra_I.STL" />
      </geometry>
      <material
        name="">
        <color
          rgba="0.792156862745098 0.819607843137255 0.933333333333333 1" />
      </material>
    </visual>
    <collision>
      <origin
        xyz="0 0 0"
        rpy="0 0 0" />
      <geometry>
        <mesh
          filename="package://robot_description/meshes/Garra_I.STL" />
      </geometry>
    </collision>
  </link>
  <joint name="Pinza-Garra_I" type="revolute">
    <origin
      xyz="0.045932 0.06246 -0.011557"
      rpy="0 0 0" />
    <parent
      link="Pinza" />
    <child
      link="Garra_I" />
    <axis
      xyz="0 0 1" />
    <limit
      lower="-0.017039"
      upper="0.76836"
      effort="0"
      velocity="0" />
  </joint>

  <!-- LIDAR -->
  <link name="base_scan">
    <inertial>
      <origin
        xyz="-0.0121843807964251 -0.000551182694658843 -0.0287550637533284"
        rpy="0 0 0" />
      <mass
        value="0.0730821532799712" />
      <inertia
        ixx="1.96273419631263E-05"
        ixy="-4.70337860049989E-07"
        ixz="4.44875499682959E-07"
        iyy="2.40792050345337E-05"
        iyz="5.24047817854105E-08"
        izz="4.14175057497245E-05" />
    </inertial>
    <visual>
      <origin
        xyz="0 0 0"
        rpy="0 0 0" />
      <geometry>
        <mesh
          filename="package://robot_description/meshes/Lidar.STL" />
      </geometry>
      <material
        name="">
        <color
          rgba="0.792156862745098 0.819607843137255 0.933333333333333 1" />
      </material>
    </visual>
    <collision>
      <origin
        xyz="0 0 0"
        rpy="0 0 0" />
      <geometry>
        <mesh
          filename="package://robot_description/meshes/Lidar.STL" />
      </geometry>
    </collision>
  </link>
  <joint name="lidar_joint" type="fixed">
    <origin
      xyz="0.16111 8.8011E-05 0.13038"
      rpy="0 0 0" />
    <parent
      link="base_link" />
    <child
      link="base_scan" />
    <axis
      xyz="0 0 0" />
  </joint>

  <!-- Neck -->
  <link name="neck_link">
    <inertial>
      <origin
        xyz="0.0470517349686886 0.0123919567767552 -0.00720656108065509"
        rpy="0 0 0" />
      <mass
        value="0.0123607422626627" />
      <inertia
        ixx="3.82073961685766E-06"
        ixy="-2.35941568160262E-06"
        ixz="2.98718036301739E-07"
        iyy="6.17958376424488E-06"
        iyz="-6.2747610746023E-08"
        izz="8.92356852920518E-06" />
    </inertial>
    <visual>
      <origin
        xyz="0 0 0"
        rpy="0 0 0" />
      <geometry>
        <mesh
          filename="package://robot_description/meshes/Cuello.STL" />
      </geometry>
      <material
        name="">
        <color
          rgba="0.792156862745098 0.819607843137255 0.933333333333333 1" />
      </material>
    </visual>
    <collision>
      <origin
        xyz="0 0 0"
        rpy="0 0 0" />
      <geometry>
        <mesh
          filename="package://robot_description/meshes/Cuello.STL" />
      </geometry>
    </collision>
  </link>
  <joint name="neck_joint" type="revolute">
    <origin
      xyz="0.083 -0.018139 1.6763"
      rpy="0 0 0" />
    <parent
      link="base_link" />
    <child
      link="neck_link" />
    <axis
      xyz="0 1 0" />
    <limit
      lower="0"
      upper="0"
      effort="0"
      velocity="0" />
  </joint>

  <!-- Camera -->
  <link name="camera">
    <inertial>
      <origin
        xyz="0.069607946372356 0.0203854936510277 0.000719459986366688"
        rpy="0 0 0" />
      <mass
        value="0.0447520630064878" />
      <inertia
        ixx="2.72774898672935E-05"
        ixy="2.4435672012364E-07"
        ixz="-1.38631264252966E-09"
        iyy="3.94471446072863E-06"
        iyz="-2.1932086349915E-09"
        izz="2.73620409048763E-05" />
    </inertial>
    <visual>
      <origin
        xyz="0 0 0"
        rpy="0 0 0" />
      <geometry>
        <mesh
          filename="package://robot_description/meshes/Camara.STL" />
      </geometry>
      <material
        name="">
        <color
          rgba="0.792156862745098 0.819607843137255 0.933333333333333 1" />
      </material>
    </visual>
    <collision>
      <origin
        xyz="0 0 0"
        rpy="0 0 0" />
      <geometry>
        <mesh
          filename="package://robot_description/meshes/Camara.STL" />
      </geometry>
    </collision>
  </link>
  <joint name="camera_joint" type="fixed">
    <origin
      xyz="0 0 0"
      rpy="0 0.8 0" />
    <parent
      link="neck_link" />
    <child
      link="camera" />
    <axis
      xyz="0 0 0" />
  </joint>

  <!-- Camera Rgb Frame -->
  <link name="camera_rgb_frame">
  </link>
  <joint name="camera_optical_joint" type="fixed">
    <origin xyz="0 0 0" rpy="-1.5707 0 -1.5707"/>
    <parent link="camera"/>
    <child link="camera_rgb_frame"/>
  </joint>

  <!-- Camera Depth Frame -->
  <link name="camera_depth_frame">
  </link>
  <joint name="camera_depth_joint" type="fixed">
    <origin xyz="0 0 0" rpy="-1.5707 0 -1.5707"/>
    <parent link="camera"/>
    <child link="camera_depth_frame"/>
  </joint>

</robot>
