<?xml version="1.0" encoding="utf-8"?>

<robot name="robot_description" 
  xmlns:xacro="http://www.ros.org/wiki/xacro">

  <xacro:include filename="$(find robot_description)/urdf/materials.xacro" />
  <xacro:include filename="$(find robot_description)/urdf/robot_nav.gazebo.xacro" />

  <virtual_joint name="world_joint" type="planar" parent_frame="odom" child_link="base_footprint"/>

  <link name="base_footprint"></link> 

  <!-- Base -->
  <link name="base_link">
    <inertial>
      <origin
        xyz="-0.140101678990613 0.00114478625174916 0.287628607282214"
        rpy="0 0 0" />
      <mass
        value="18.1215133555874" />
      <inertia
        ixx="0.749373660807314"
        ixy="-2.04114489679086E-05"
        ixz="0.0287031101977871"
        iyy="0.757729413836533"
        iyz="-2.12902753512747E-05"
        izz="0.727122404257033" />
    </inertial>
    <visual>
      <origin
        xyz="0 0 0"
        rpy="0 0 0" />
      <geometry>
        <mesh
          filename="package://robot_description/meshes/base_link.STL" />
      </geometry>
      <material
        name="">
        <color
          rgba="0.792156862745098 0.819607843137255 0.933333333333333 1" />
      </material>
    </visual>
    <collision>
      <origin
        xyz="0 0 0"
        rpy="0 0 0" />
      <geometry>
        <mesh
          filename="package://robot_description/meshes/base_link.STL" />
      </geometry>
    </collision>
  </link>
  <joint name="base_joint" type="fixed">
    <origin xyz="0 0 0" rpy="0 0 0"/>
    <parent link="base_footprint"/>
    <child link="base_link"/>
  </joint>

  <!-- Wheel 1 -->
  <link name="R1">
    <inertial>
      <origin
        xyz="3.23195320450775E-07 -0.0179507439124115 1.34412548334628E-07"
        rpy="0 0 0" />
      <mass
        value="0.27570630673027" />
      <inertia
        ixx="6.88913760503531E-05"
        ixy="-9.99707194725952E-11"
        ixz="2.32024543753798E-10"
        iyy="9.7675702655705E-05"
        iyz="2.38192945242156E-10"
        izz="6.88909173459932E-05" />
    </inertial>
    <visual>
      <origin
        xyz="0 0 0"
        rpy="0 0 0" />
      <geometry>
        <mesh
          filename="package://robot_description/meshes/R1.STL" />
      </geometry>
      <material
        name="">
        <color
          rgba="1 1 1 1" />
      </material>
    </visual>
    <collision>
      <origin
        xyz="0 0 0"
        rpy="0 0 0" />
      <geometry>
        <mesh
          filename="package://robot_description/meshes/R1.STL" />
      </geometry>
    </collision>
  </link>
  <joint name="Chasis-R1" type="continuous">
    <origin
      xyz="0.13960999018429 -0.224000012165135 -0.0268998000000014"
      rpy="0 0 0" />
    <parent
      link="base_link" />
    <child
      link="R1" />
    <axis
      xyz="0 1 0" />
  </joint>

  <!-- Wheel 2 -->
  <link name="R2">
    <inertial>
      <origin
        xyz="3.32396812519065E-07 0.0179292857255078 1.09213569882138E-07"
        rpy="0 0 0" />
      <mass
        value="0.275706306313456" />
      <inertia
        ixx="6.88914080188531E-05"
        ixy="-8.21254945713304E-11"
        ixz="1.95157168736736E-10"
        iyy="9.76757022851765E-05"
        iyz="2.44874061876534E-10"
        izz="6.88908849846178E-05" />
    </inertial>
    <visual>
      <origin
        xyz="0 0 0"
        rpy="0 0 0" />
      <geometry>
        <mesh
          filename="package://robot_description/meshes/R2.STL" />
      </geometry>
      <material
        name="">
        <color
          rgba="1 1 1 1" />
      </material>
    </visual>
    <collision>
      <origin
        xyz="0 0 0"
        rpy="0 0 0" />
      <geometry>
        <mesh
          filename="package://robot_description/meshes/R2.STL" />
      </geometry>
    </collision>
  </link>
  <joint name="Chasis-R2" type="continuous">
    <origin
      xyz="0.13960999018429 0.223999987834865 -0.0268998000000016"
      rpy="0 0 0" />
    <parent
      link="base_link" />
    <child
      link="R2" />
    <axis
      xyz="0 1 0" />
  </joint>

  <!-- Wheel 3 -->
  <link name="R3">
    <inertial>
      <origin
        xyz="3.3240531571721E-07 -0.0179507439283899 1.09240773635277E-07"
        rpy="0 0 0" />
      <mass
        value="0.275706305841014" />
      <inertia
        ixx="6.88914080095044E-05"
        ixy="-8.20813841371881E-11"
        ixz="1.95067792411591E-10"
        iyy="9.76757020468613E-05"
        iyz="2.44897502150705E-10"
        izz="6.88908846889313E-05" />
    </inertial>
    <visual>
      <origin
        xyz="0 0 0"
        rpy="0 0 0" />
      <geometry>
        <mesh
          filename="package://robot_description/meshes/R3.STL" />
      </geometry>
      <material
        name="">
        <color
          rgba="1 1 1 1" />
      </material>
    </visual>
    <collision>
      <origin
        xyz="0 0 0"
        rpy="0 0 0" />
      <geometry>
        <mesh
          filename="package://robot_description/meshes/R3.STL" />
      </geometry>
    </collision>
  </link>
  <joint name="Chasis-R3" type="continuous">
    <origin
      xyz="-0.29339000981571 -0.224000012165135 -0.0263997999996424"
      rpy="0 0 0" />
    <parent
      link="base_link" />
    <child
      link="R3" />
    <axis
      xyz="0 1 0" />
  </joint>

  <!-- Wheel 4 -->
  <link name="R4">
    <inertial>
      <origin
        xyz="3.32392385726799E-07 0.017929285725242 1.09201910493406E-07"
        rpy="0 0 0" />
      <mass
        value="0.275706305793894" />
      <inertia
        ixx="6.88914078143537E-05"
        ixy="-8.21406947723185E-11"
        ixz="1.95123343999065E-10"
        iyy="9.76757019588434E-05"
        iyz="2.44857261652816E-10"
        izz="6.88908847877444E-05" />
    </inertial>
    <visual>
      <origin
        xyz="0 0 0"
        rpy="0 0 0" />
      <geometry>
        <mesh
          filename="package://robot_description/meshes/R4.STL" />
      </geometry>
      <material
        name="">
        <color
          rgba="1 1 1 1" />
      </material>
    </visual>
    <collision>
      <origin
        xyz="0 0 0"
        rpy="0 0 0" />
      <geometry>
        <mesh
          filename="package://robot_description/meshes/R4.STL" />
      </geometry>
    </collision>
  </link>
  <joint name="Chasis-R4" type="continuous">
    <origin
      xyz="-0.29339000981571 0.223999987834865 -0.0268998000000015"
      rpy="0 0 0" />
    <parent
      link="base_link" />
    <child
      link="R4" />
    <axis
      xyz="0 1 0" />
  </joint>

  <!-- LIDAR -->
  <link name="base_scan">
    <inertial>
      <origin
        xyz="-0.0121843807964251 -0.000551182694658843 -0.0287550637533284"
        rpy="0 0 0" />
      <mass
        value="0.0730821532799712" />
      <inertia
        ixx="1.96273419631263E-05"
        ixy="-4.70337860049989E-07"
        ixz="4.44875499682959E-07"
        iyy="2.40792050345337E-05"
        iyz="5.24047817854105E-08"
        izz="4.14175057497245E-05" />
    </inertial>
    <visual>
      <origin
        xyz="0 0 0"
        rpy="0 0 0" />
      <geometry>
        <mesh
          filename="package://robot_description/meshes/Lidar.STL" />
      </geometry>
      <material
        name="">
        <color
          rgba="0.792156862745098 0.819607843137255 0.933333333333333 1" />
      </material>
    </visual>
    <collision>
      <origin
        xyz="0 0 0"
        rpy="0 0 0" />
      <geometry>
        <mesh
          filename="package://robot_description/meshes/Lidar.STL" />
      </geometry>
    </collision>
  </link>
  <joint name="lidar_joint" type="fixed">
    <origin
      xyz="0.16111 8.8011E-05 0.13038"
      rpy="0 0 0" />
    <parent
      link="base_link" />
    <child
      link="base_scan" />
    <axis
      xyz="0 0 0" />
  </joint>

</robot>
