<?xml version="1.0" ?>
<!-- =================================================================================== -->
<!-- |    This document was autogenerated by xacro from /home/jose/Desktop/Roborregos/Robocup-Home/catkin_home/src/robot_description/urdf/dashgo.urdf.xacro | -->
<!-- |    EDITING THIS FILE BY HAND IS NOT RECOMMENDED                                 | -->
<!-- =================================================================================== -->
<!-- This URDF was automatically created by SolidWorks to URDF Exporter! Originally created by Stephen Brawner (brawner@gmail.com) 
     Commit Version: 1.6.0-4-g7f85cfe  Build Version: 1.6.7995.38578
     For more information, please see http://wiki.ros.org/sw_urdf_exporter -->
<robot name="dashgo">
    <virtual_joint child_link="internal_odom" name="world_joint" parent_frame="odom" type="planar" />
    <!-- ############################BASE_MOVEMENT############################## -->
    <link name="internal_odom" />
    <joint name="internal_odom_joint" type="fixed">
        <origin rpy="0 0 0" xyz="0 0 0" />
        <parent link="internal_odom" />
        <child link="internal_odom_inertia" />
    </joint>
    <link name="internal_odom_inertia">
        <inertial>
            <mass value="0.10" />
            <!--  assume as square, hence inertia = (1/12) * m * (a^2 + b^2)  -->
            <inertia ixx="0.000729" ixy="0" ixz="0" iyy="0.000729" iyz="0" izz="0.000729" />
        </inertial>
    </link>
    <joint name="odom_y" type="prismatic">
        <axis xyz="0 1 0" />
        <parent link="internal_odom_inertia" />
        <child link="odom_yx_link" />
        <limit effort="1" lower="0" upper="0" velocity="0.4" />
        <dynamics damping="0.7" friction="2" />
    </joint>
    <link name="odom_yx_link">
        <inertial>
            <mass value="0.10" />
            <!--  assume as square, hence inertia = (1/12) * m * (a^2 + b^2)  -->
            <inertia ixx="0.000729" ixy="0" ixz="0" iyy="0.000729" iyz="0" izz="0.000729" />
        </inertial>
    </link>
    <joint name="odom_x" type="prismatic">
        <axis xyz="1 0 0" />
        <parent link="odom_yx_link" />
        <child link="odom_xr_link" />
        <limit effort="1" lower="-10" upper="10" velocity="0.4" />
        <dynamics damping="0.7" friction="2" />
    </joint>
    <link name="odom_xr_link">
        <inertial>
            <mass value="0.10" />
            <!--  assume as square, hence inertia = (1/12) * m * (a^2 + b^2)  -->
            <inertia ixx="0.000729" ixy="0" ixz="0" iyy="0.000729" iyz="0" izz="0.000729" />
        </inertial>
    </link>
    <joint name="odom_r" type="revolute">
        <axis xyz="0 0 1" />
        <parent link="odom_xr_link" />
        <child link="base_link" />
        <limit effort="1" lower="-6.2832" upper="6.2832" velocity="0.4" />
        <dynamics damping="0.7" friction="2" />
    </joint>
    <!-- ########################################################################### -->
    <link name="base_link" />
    <link name="Base">
        <inertial>
            <origin rpy="0 0 0" xyz="0.00112427313846248 0.0541261508672339 0.24050906361582" />
            <mass value="5.93374358050292" />
            <inertia ixx="0.102381643014475" ixy="-2.49686782363747E-05" ixz="7.32458903286202E-10" iyy="0.103854959010774" iyz="0.000125261050360604" izz="0.0793094023514086" />
        </inertial>
        <visual>
            <origin rpy="0 0 0" xyz="0 0 0" />
            <geometry>
                <mesh filename="package://robot_description/meshes/Dashgo/Base.STL" />
            </geometry>
            <material name="">
                <color rgba="0.792156862745098 0.819607843137255 0.933333333333333 1" />
            </material>
        </visual>
        <collision>
            <origin rpy="0 0 0" xyz="0 0 0" />
            <geometry>
                <mesh filename="package://robot_description/meshes/Dashgo/Base.STL" />
            </geometry>
        </collision>
    </link>
    <joint name="base_joint" type="fixed">
        <origin rpy="0 0 0" xyz="0 0 0" />
        <parent link="base_link" />
        <child link="Base" />
    </joint>
    <link name="Llanta1">
        <inertial>
            <origin rpy="0 0 0" xyz="3.88578058618805E-16 6.52256026967279E-16 0.0200000000000003" />
            <mass value="0.528918539158378" />
            <inertia ixx="0.000631308353030454" ixy="-1.64320882748444E-36" ixz="1.72050413075699E-18" iyy="0.000631308353030454" iyz="-1.04568558444466E-36" izz="0.00112157176228534" />
        </inertial>
        <visual>
            <origin rpy="0 0 0" xyz="0 0 0" />
            <geometry>
                <mesh filename="package://robot_description/meshes/Dashgo/Llanta1.STL" />
            </geometry>
            <material name="">
                <color rgba="0.792156862745098 0.819607843137255 0.933333333333333 1" />
            </material>
        </visual>
        <collision>
            <origin rpy="0 0 0" xyz="0 0 0" />
            <geometry>
                <mesh filename="package://robot_description/meshes/Dashgo/Llanta1.STL" />
            </geometry>
        </collision>
    </link>
    <joint name="Llanta1Cont" type="continuous">
        <origin rpy="1.5707963267949 0 1.5707963267949" xyz="0.145999999999999 0.1155 0.0375" />
        <parent link="Base" />
        <child link="Llanta1" />
        <axis xyz="0 0 1" />
    </joint>
    <link name="Llanta2">
        <inertial>
            <origin rpy="0 0 0" xyz="-1.38777878078145E-17 -1.11022302462516E-16 -0.02" />
            <mass value="0.528918539158378" />
            <inertia ixx="0.000631308353030454" ixy="-8.470329472543E-22" ixz="-9.10263751530836E-20" iyy="0.000631308353030454" iyz="4.50857846912387E-20" izz="0.00112157176228534" />
        </inertial>
        <visual>
            <origin rpy="0 0 0" xyz="0 0 0" />
            <geometry>
                <mesh filename="package://robot_description/meshes/Dashgo/Llanta2.STL" />
            </geometry>
            <material name="">
                <color rgba="0.792156862745098 0.819607843137255 0.933333333333333 1" />
            </material>
        </visual>
        <collision>
            <origin rpy="0 0 0" xyz="0 0 0" />
            <geometry>
                <mesh filename="package://robot_description/meshes/Dashgo/Llanta2.STL" />
            </geometry>
        </collision>
    </link>
    <joint name="Llanta2Cont" type="continuous">
        <origin rpy="1.5707963267949 0.0209487637131551 1.5707963267949" xyz="-0.146 0.1155 0.0375" />
        <parent link="Base" />
        <child link="Llanta2" />
        <axis xyz="0 0 1" />
    </joint>
    <link name="Loca1">
        <inertial>
            <origin rpy="0 0 0" xyz="0 0.0345546529721542 -2.77555756156289E-17" />
            <mass value="0.0167352759899297" />
            <inertia ixx="7.54150196205056E-06" ixy="1.16160786447369E-21" ixz="-8.76254817321673E-22" iyy="5.85653067123054E-06" iyz="-1.79120955050736E-21" izz="7.09027556219276E-06" />
        </inertial>
        <visual>
            <origin rpy="0 0 0" xyz="0 0 0" />
            <geometry>
                <mesh filename="package://robot_description/meshes/Dashgo/Loca1.STL" />
            </geometry>
            <material name="">
                <color rgba="0.792156862745098 0.819607843137255 0.933333333333333 1" />
            </material>
        </visual>
        <collision>
            <origin rpy="0 0 0" xyz="0 0 0" />
            <geometry>
                <mesh filename="package://robot_description/meshes/Dashgo/Loca1.STL" />
            </geometry>
        </collision>
    </link>
    <joint name="Loca1Cont" type="continuous">
        <origin rpy="1.5707963267949 0 0" xyz="-0.09 -0.072 0" />
        <parent link="Base" />
        <child link="Loca1" />
        <axis xyz="0 1 0" />
    </joint>
    <link name="LlantaLoca1">
        <inertial>
            <origin rpy="0 0 0" xyz="1.38777878078145E-17 -0.00741632050454701 1.38777878078145E-17" />
            <mass value="0.0694291976443345" />
            <inertia ixx="3.17985725211052E-05" ixy="-5.21349495168481E-38" ixz="3.52930394689292E-22" iyy="1.95153903045283E-05" iyz="7.67877008722515E-41" izz="1.95153903045283E-05" />
        </inertial>
        <visual>
            <origin rpy="0 0 0" xyz="0 0 0" />
            <geometry>
                <mesh filename="package://robot_description/meshes/Dashgo/LlantaLoca1.STL" />
            </geometry>
            <material name="">
                <color rgba="0.792156862745098 0.819607843137255 0.933333333333333 1" />
            </material>
        </visual>
        <collision>
            <origin rpy="0 0 0" xyz="0 0 0" />
            <geometry>
                <mesh filename="package://robot_description/meshes/Dashgo/LlantaLoca1.STL" />
            </geometry>
        </collision>
    </link>
    <joint name="LlantaLoca1Cont" type="continuous">
        <origin rpy="0 0 0" xyz="0 0.01 0" />
        <parent link="Loca1" />
        <child link="LlantaLoca1" />
        <axis xyz="1 0 0" />
    </joint>
    <link name="Loca2">
        <inertial>
            <origin rpy="0 0 0" xyz="1.38777878078145E-17 0.0345546529721542 2.77555756156289E-17" />
            <mass value="0.0167352759899297" />
            <inertia ixx="7.54150196205057E-06" ixy="-2.55901620932607E-21" ixz="3.17637355220363E-22" iyy="5.85653067123054E-06" iyz="2.07178253258396E-21" izz="7.09027556219276E-06" />
        </inertial>
        <visual>
            <origin rpy="0 0 0" xyz="0 0 0" />
            <geometry>
                <mesh filename="package://robot_description/meshes/Dashgo/Loca2.STL" />
            </geometry>
            <material name="">
                <color rgba="0.792156862745098 0.819607843137255 0.933333333333333 1" />
            </material>
        </visual>
        <collision>
            <origin rpy="0 0 0" xyz="0 0 0" />
            <geometry>
                <mesh filename="package://robot_description/meshes/Dashgo/Loca2.STL" />
            </geometry>
        </collision>
    </link>
    <joint name="Loca2Cont" type="continuous">
        <origin rpy="1.5707963267949 0 0.119243381039157" xyz="0.09 -0.072 0" />
        <parent link="Base" />
        <child link="Loca2" />
        <axis xyz="0 1 0" />
    </joint>
    <link name="LlantaLoca2">
        <inertial>
            <origin rpy="0 0 0" xyz="0 -0.00469061857919597 -0.00574455456677592" />
            <mass value="0.0694291976443344" />
            <inertia ixx="3.17985725211052E-05" ixy="-8.78796682776337E-21" ixz="8.470329472543E-22" iyy="1.95153903045283E-05" iyz="-1.6940658945086E-21" izz="1.95153903045284E-05" />
        </inertial>
        <visual>
            <origin rpy="0 0 0" xyz="0 0 0" />
            <geometry>
                <mesh filename="package://robot_description/meshes/Dashgo/LlantaLoca2.STL" />
            </geometry>
            <material name="">
                <color rgba="0.792156862745098 0.819607843137255 0.933333333333333 1" />
            </material>
        </visual>
        <collision>
            <origin rpy="0 0 0" xyz="0 0 0" />
            <geometry>
                <mesh filename="package://robot_description/meshes/Dashgo/LlantaLoca2.STL" />
            </geometry>
        </collision>
    </link>
    <joint name="LlantaLoca2Cont" type="continuous">
        <origin rpy="-0.886055251315474 0 0" xyz="0 0.01 0" />
        <parent link="Loca2" />
        <child link="LlantaLoca2" />
        <axis xyz="1 0 0" />
    </joint>
    <link name="Lidar">
        <inertial>
            <origin rpy="0 0 0" xyz="-9.49517221724887E-50 0.0125 -1.38777878078145E-17" />
            <mass value="0.0962112750161874" />
            <inertia ixx="3.44757068808005E-05" ixy="8.13422838622583E-38" ixz="1.3254524700622E-52" iyy="5.89294059474148E-05" iyz="-6.00991536754997E-37" izz="3.44757068808005E-05" />
        </inertial>
        <visual>
            <origin rpy="0 0 0" xyz="0 0 0" />
            <geometry>
                <mesh filename="package://robot_description/meshes/Dashgo/Lidar.STL" />
            </geometry>
            <material name="">
                <color rgba="0.792156862745098 0.819607843137255 0.933333333333333 1" />
            </material>
        </visual>
        <collision>
            <origin rpy="0 0 0" xyz="0 0 0" />
            <geometry>
                <mesh filename="package://robot_description/meshes/Dashgo/Lidar.STL" />
            </geometry>
        </collision>
    </link>
    <joint name="Lidar1Cont" type="fixed">
        <origin rpy="1.5707963267949 0 0" xyz="0 -0.11 0.12" />
        <parent link="Base" />
        <child link="Lidar" />
    </joint>
    <link name="RevCam1">
        <inertial>
            <origin rpy="0 0 0" xyz="-0.00218640113558178 0.0383778465870379 -0.00515828443968216" />
            <mass value="0.0807173201754215" />
            <inertia ixx="2.37796512993046E-05" ixy="8.55530391588451E-07" ixz="-2.49698267928072E-07" iyy="1.83589770932126E-05" iyz="-4.19202714077016E-06" izz="2.27836705307722E-05" />
        </inertial>
        <visual>
            <origin rpy="0 0 0" xyz="0 0 0" />
            <geometry>
                <mesh filename="package://robot_description/meshes/Dashgo/RevCam1.STL" />
            </geometry>
            <material name="">
                <color rgba="0.792156862745098 0.819607843137255 0.933333333333333 1" />
            </material>
        </visual>
        <collision>
            <origin rpy="0 0 0" xyz="0 0 0" />
            <geometry>
                <mesh filename="package://robot_description/meshes/Dashgo/RevCam1.STL" />
            </geometry>
        </collision>
    </link>
    <joint name="Cam1Rev1" type="revolute">
        <origin rpy="1.5708 0 0.034703" xyz="0.001 0.0505 1.545" />
        <parent link="Base" />
        <child link="RevCam1" />
        <axis xyz="0 1 0" />
        <limit effort="0" lower="-0.5236" upper="0.5236" velocity="0" />
    </joint>
    <link name="RevCam2">
        <inertial>
            <origin rpy="0 0 0" xyz="-0.00391793043436037 -0.0102932368661919 0.0320850186207662" />
            <mass value="0.0649807233686399" />
            <inertia ixx="2.601013236039E-05" ixy="-1.98669220487697E-07" ixz="-5.07308429498073E-06" iyy="4.18390847409689E-05" iyz="3.16753039765753E-07" izz="3.84670102617888E-05" />
        </inertial>
        <visual>
            <origin rpy="0 0 0" xyz="0 0 0" />
            <geometry>
                <mesh filename="package://robot_description/meshes/Dashgo/RevCam2.STL" />
            </geometry>
            <material name="">
                <color rgba="0.792156862745098 0.819607843137255 0.933333333333333 1" />
            </material>
        </visual>
        <collision>
            <origin rpy="0 0 0" xyz="0 0 0" />
            <geometry>
                <mesh filename="package://robot_description/meshes/Dashgo/RevCam2.STL" />
            </geometry>
        </collision>
    </link>
    <joint name="Cam1Rev2" type="revolute">
        <origin rpy="0.0 0.0 0.0" xyz="0 0.05 0" />
        <parent link="RevCam1" />
        <child link="RevCam2" />
        <axis xyz="0.9913 0 0.13162" />
        <limit effort="0" lower="-0.5236" upper="0.5236" velocity="0" />
    </joint>
    <link name="Cam1">
        <inertial>
            <origin rpy="0 0 0" xyz="0.0 0.0 0.0" />
            <mass value="0.152258268245259" />
            <inertia ixx="2.28182702795267E-05" ixy="-2.56241481012795E-09" ixz="-6.38770400261561E-09" iyy="0.000372324880916607" iyz="-3.15065555476608E-08" izz="0.000374741839243315" />
        </inertial>
        <visual>
            <origin rpy="3.1416 3.1416 1.57" xyz="-0.02 0 -0.035" />
            <geometry>
                <mesh filename="package://robot_description/meshes/Dashgo/Cam1.STL" />
            </geometry>
            <material name="">
                <color rgba="0.176470588235294 0.176470588235294 0.176470588235294 1" />
            </material>
        </visual>
        <collision>
            <origin rpy="0 0 0" xyz="0 0 0" />
            <geometry>
                <mesh filename="package://robot_description/meshes/Dashgo/Cam1.STL" />
            </geometry>
        </collision>
    </link>
    <joint name="Cam1Fix" type="fixed">
        <origin rpy="0 0.822 -1.54" xyz="0.001 0.1 1.5325" />
        <parent link="Base" />
        <child link="Cam1" />
        <axis xyz="0 0 0" />
    </joint>
    <link name="BaseBrazo">
        <inertial>
            <origin rpy="0 0 0" xyz="3.67638287580227E-16 4.9999999999939E-05 -6.24500451351651E-17" />
            <mass value="0.00121022002997899" />
            <inertia ixx="1.17272637070328E-06" ixy="6.31088724176809E-28" ixz="-2.66571877092316E-23" iyy="2.34545072437318E-06" iyz="8.8102553557097E-43" izz="1.17272637070328E-06" />
        </inertial>
        <visual>
            <origin rpy="0 0 0" xyz="0 0 0" />
            <geometry>
                <mesh filename="package://robot_description/meshes/Dashgo/BaseBrazo.STL" />
            </geometry>
            <material name="">
                <color rgba="0.792156862745098 0.819607843137255 0.933333333333333 1" />
            </material>
        </visual>
        <collision>
            <origin rpy="0 0 0" xyz="0 0 0" />
            <geometry>
                <mesh filename="package://robot_description/meshes/Dashgo/BaseBrazo.STL" />
            </geometry>
        </collision>
    </link>
    <joint name="Bra1Fix" type="fixed">
        <origin rpy="0 0 0" xyz="0 0.054 0.458" />
        <parent link="Base" />
        <child link="BaseBrazo" />
        <axis xyz="0 0 0" />
    </joint>
    <link name="Cam2Rev">
        <inertial>
            <origin rpy="0 0 0" xyz="0.00682985175837994 -0.000385575645117986 -0.0349999944296163" />
            <mass value="0.034811214257021" />
            <inertia ixx="2.55962188508613E-05" ixy="-2.57231687004444E-08" ixz="-1.01276020904133E-12" iyy="2.69230048658024E-05" iyz="-2.47763740414839E-12" izz="1.54258334654207E-05" />
        </inertial>
        <visual>
            <origin rpy="0 0 0" xyz="0 0 0" />
            <geometry>
                <mesh filename="package://robot_description/meshes/Dashgo/Cam2Rev.STL" />
            </geometry>
            <material name="">
                <color rgba="0.792156862745098 0.819607843137255 0.933333333333333 1" />
            </material>
        </visual>
        <collision>
            <origin rpy="0 0 0" xyz="0 0 0" />
            <geometry>
                <mesh filename="package://robot_description/meshes/Dashgo/Cam2Rev.STL" />
            </geometry>
        </collision>
    </link>
    <joint name="Cam2Rev" type="revolute">
        <origin rpy="-1.5708 0.52947 -1.5708" xyz="0.1175 -0.16539 0.50877" />
        <parent link="Base" />
        <child link="Cam2Rev" />
        <axis xyz="0 0 1" />
        <limit effort="0" lower="-0.5236" upper="0.5236" velocity="0" />
    </joint>
    <link name="Cam2">
        <inertial>
            <origin rpy="0 0 0" xyz="2.78178449257538E-06 0.0154104478086763 0.043479722430293" />
            <mass value="0.152258366821035" />
            <inertia ixx="2.28178239715899E-05" ixy="-2.07069498673643E-09" ixz="-6.33175797043533E-09" iyy="0.000372337777425285" iyz="-1.79769097625592E-07" izz="0.000374729108133576" />
        </inertial>
        <visual>
            <origin rpy="0 0 0" xyz="0 0 0" />
            <geometry>
                <mesh filename="package://robot_description/meshes/Dashgo/Cam2.STL" />
            </geometry>
            <material name="">
                <color rgba="0.176470588235294 0.176470588235294 0.176470588235294 1" />
            </material>
        </visual>
        <collision>
            <origin rpy="0 0 0" xyz="0 0 0" />
            <geometry>
                <mesh filename="package://robot_description/meshes/Dashgo/Cam2.STL" />
            </geometry>
        </collision>
    </link>
    <joint name="Cam2Fixed" type="fixed">
        <origin rpy="1.47657636910629 1.5707963267949 0" xyz="-0.0015140313995038 0.0417760943111851 -0.034999943378925" />
        <parent link="Cam2Rev" />
        <child link="Cam2" />
        <axis xyz="0 0 0" />
    </joint>
    <!--
  Author: Jason Peng <jason@ufactory.cc>
  Contributers:
-->
    <gazebo>
        <plugin filename="libgazebo_ros_control.so" name="gazebo_ros_control">
            <robotNamespace>/xarm</robotNamespace>
            <!-- <controlPeriod>0.0001</controlPeriod> -->
            <robotSimType>gazebo_ros_control/DefaultRobotHWSim</robotSimType>
            <legacyModeNS>true</legacyModeNS>
            <!-- <preserveWorldVelocity>true</preserveWorldVelocity> -->
        </plugin>
    </gazebo>
    <joint name="world_joint" type="fixed">
        <parent link="BaseBrazo" />
        <child link="link_base" />
        <origin rpy="0 0 0" xyz="0 0 0" />
    </joint>
    <material name="Black">
        <color rgba="0.0 0.0 0.0 1.0" />
    </material>
    <material name="Red">
        <color rgba="0.8 0.0 0.0 1.0" />
    </material>
    <material name="White">
        <color rgba="1.0 1.0 1.0 1.0" />
    </material>
    <material name="Silver">
        <color rgba="0.753 0.753 0.753 1.0" />
    </material>
    <link name="link_base">
        <inertial>
            <origin rpy="0 0 0" xyz="-0.00218 -0.00023 0.08604" />
            <mass value="1.95" />
            <inertia ixx="0.004805" ixy="-8.33E-06" ixz="0.00026847" iyy="0.0050349" iyz="7.23E-06" izz="0.0025418" />
        </inertial>
        <visual>
            <origin rpy="0 0 0" xyz="0 0 0" />
            <geometry>
                <mesh filename="package://xarm_description/meshes/xarm5/visual/base_link.STL" />
            </geometry>
            <material name="White" />
        </visual>
        <collision>
            <origin rpy="0 0 0" xyz="0 0 0" />
            <geometry>
                <mesh filename="package://xarm_description/meshes/xarm5/visual/base_link.STL" />
            </geometry>
        </collision>
    </link>
    <link name="link1">
        <inertial>
            <origin rpy="0 0 0" xyz="0.00016 0.02064 -0.01556" />
            <mass value="1.85" />
            <inertia ixx="0.0046885" ixy="-8.67E-06" ixz="2.439E-05" iyy="0.0041688" iyz="0.0006114" izz="0.0024758" />
        </inertial>
        <visual>
            <origin rpy="0 0 0" xyz="0 0 0" />
            <geometry>
                <mesh filename="package://xarm_description/meshes/xarm5/visual/link1.STL" />
            </geometry>
            <material name="White" />
        </visual>
        <collision>
            <origin rpy="0 0 0" xyz="0 0 0" />
            <geometry>
                <mesh filename="package://xarm_description/meshes/xarm5/visual/link1.STL" />
            </geometry>
        </collision>
    </link>
    <joint name="joint1" type="revolute">
        <origin rpy="0 0 0" xyz="0 0 0.267" />
        <parent link="link_base" />
        <child link="link1" />
        <axis xyz="0 0 1" />
        <limit effort="50" lower="-6.283185307179586" upper="6.283185307179586" velocity="3.14" />
        <dynamics damping="10" friction="1" />
    </joint>
    <link name="link2">
        <inertial>
            <origin rpy="0 0 0" xyz="0.0351 -0.21375 0.02835" />
            <mass value="1.71" />
            <inertia ixx="0.024904" ixy="-0.004271" ixz="-0.0008356" iyy="0.004901" iyz="0.0052393" izz="0.0238188" />
        </inertial>
        <visual>
            <origin rpy="0 0 0" xyz="0 0 0" />
            <geometry>
                <mesh filename="package://xarm_description/meshes/xarm5/visual/link2.STL" />
            </geometry>
            <material name="White" />
        </visual>
        <collision>
            <origin rpy="0 0 0" xyz="0 0 0" />
            <geometry>
                <mesh filename="package://xarm_description/meshes/xarm5/visual/link2.STL" />
            </geometry>
        </collision>
    </link>
    <joint name="joint2" type="revolute">
        <origin rpy="-1.5708 0 0" xyz="0 0 0" />
        <parent link="link1" />
        <child link="link2" />
        <axis xyz="0 0 1" />
        <limit effort="50" lower="-2.059" upper="2.0944" velocity="3.14" />
        <dynamics damping="10" friction="1" />
    </joint>
    <link name="link3">
        <inertial>
            <origin rpy="0 0 0" xyz="0.06716 0.2299 -0.00249" />
            <mass value="1.74" />
            <inertia ixx="0.0335922" ixy="0.0040788" ixz="-0.0014658" iyy="0.0055857" iyz="-0.0080609" izz="0.0318905" />
        </inertial>
        <visual>
            <origin rpy="0 0 0" xyz="0 0 0" />
            <geometry>
                <mesh filename="package://xarm_description/meshes/xarm5/visual/link3.STL" />
            </geometry>
            <material name="White" />
        </visual>
        <collision>
            <origin rpy="0 0 0" xyz="0 0 0" />
            <geometry>
                <mesh filename="package://xarm_description/meshes/xarm5/visual/link3.STL" />
            </geometry>
        </collision>
    </link>
    <joint name="joint3" type="revolute">
        <origin rpy="0 0 0" xyz="0.0535 -0.2845 0" />
        <parent link="link2" />
        <child link="link3" />
        <axis xyz="0 0 1" />
        <limit effort="30" lower="-3.927" upper="0.19198" velocity="3.14" />
        <dynamics damping="5" friction="1" />
    </joint>
    <link name="link4">
        <inertial>
            <origin rpy="0 0 0" xyz="0.0636 0.02203 0.00355" />
            <mass value="1.13" />
            <inertia ixx="0.0010927" ixy="0.0003076" ixz="-0.0002076" iyy="0.0016058" iyz="-8.863E-05" izz="0.0019148" />
        </inertial>
        <visual>
            <origin rpy="0 0 0" xyz="0 0 0" />
            <geometry>
                <mesh filename="package://xarm_description/meshes/xarm5/visual/link4.STL" />
            </geometry>
            <material name="White" />
        </visual>
        <collision>
            <origin rpy="0 0 0" xyz="0 0 0" />
            <geometry>
                <mesh filename="package://xarm_description/meshes/xarm5/visual/link4.STL" />
            </geometry>
        </collision>
    </link>
    <joint name="joint4" type="revolute">
        <origin rpy="0 0 0" xyz="0.0775 0.3425 0" />
        <parent link="link3" />
        <child link="link4" />
        <axis xyz="0 0 1" />
        <limit effort="20" lower="-1.69297" upper="3.141592653589793" velocity="3.14" />
        <dynamics damping="3" friction="1" />
    </joint>
    <link name="link5">
        <inertial>
            <origin rpy="0 0 0" xyz="-3E-05 -0.00677 -0.01098" />
            <mass value="0.16" />
            <inertia ixx="9.341E-05" ixy="0.0" ixz="0.0" iyy="5.87E-05" iyz="3.57E-06" izz="1.33E-05" />
        </inertial>
        <visual>
            <origin rpy="0 0 0" xyz="0 0 0" />
            <geometry>
                <mesh filename="package://xarm_description/meshes/xarm5/visual/link5.STL" />
            </geometry>
            <material name="Silver" />
        </visual>
        <collision>
            <origin rpy="0 0 0" xyz="0 0 0" />
            <geometry>
                <mesh filename="package://xarm_description/meshes/collision/end_tool.STL" />
            </geometry>
        </collision>
    </link>
    <joint name="joint5" type="revolute">
        <origin rpy="-1.5708 0 0" xyz="0.076 0.097 0" />
        <parent link="link4" />
        <child link="link5" />
        <axis xyz="0 0 1" />
        <limit effort="20" lower="-6.283185307179586" upper="6.283185307179586" velocity="3.14" />
        <dynamics damping="3" friction="1" />
    </joint>
    <link name="link_eef" />
    <joint name="joint_eef" type="fixed">
        <origin rpy="0 0 0" xyz="0 0 0" />
        <parent link="link5" />
        <child link="link_eef" />
    </joint>
    <transmission name="tran1">
        <type>transmission_interface/SimpleTransmission</type>
        <joint name="joint1">
            <hardwareInterface>hardware_interface/PositionJointInterface</hardwareInterface>
        </joint>
        <actuator name="motor1">
            <hardwareInterface>hardware_interface/PositionJointInterface</hardwareInterface>
            <mechanicalReduction>100</mechanicalReduction>
        </actuator>
    </transmission>
    <transmission name="tran2">
        <type>transmission_interface/SimpleTransmission</type>
        <joint name="joint2">
            <hardwareInterface>hardware_interface/PositionJointInterface</hardwareInterface>
        </joint>
        <actuator name="motor2">
            <hardwareInterface>hardware_interface/PositionJointInterface</hardwareInterface>
            <mechanicalReduction>100</mechanicalReduction>
        </actuator>
    </transmission>
    <transmission name="tran3">
        <type>transmission_interface/SimpleTransmission</type>
        <joint name="joint3">
            <hardwareInterface>hardware_interface/PositionJointInterface</hardwareInterface>
        </joint>
        <actuator name="motor3">
            <hardwareInterface>hardware_interface/PositionJointInterface</hardwareInterface>
            <mechanicalReduction>100</mechanicalReduction>
        </actuator>
    </transmission>
    <transmission name="tran4">
        <type>transmission_interface/SimpleTransmission</type>
        <joint name="joint4">
            <hardwareInterface>hardware_interface/PositionJointInterface</hardwareInterface>
        </joint>
        <actuator name="motor3">
            <hardwareInterface>hardware_interface/PositionJointInterface</hardwareInterface>
            <mechanicalReduction>100</mechanicalReduction>
        </actuator>
    </transmission>
    <transmission name="tran5">
        <type>transmission_interface/SimpleTransmission</type>
        <joint name="joint5">
            <hardwareInterface>hardware_interface/PositionJointInterface</hardwareInterface>
        </joint>
        <actuator name="motor5">
            <hardwareInterface>hardware_interface/PositionJointInterface</hardwareInterface>
            <mechanicalReduction>100</mechanicalReduction>
        </actuator>
    </transmission>
    <gazebo reference="link_base">
        <selfCollide>true</selfCollide>
    </gazebo>
    <gazebo reference="link1">
        <selfCollide>true</selfCollide>
    </gazebo>
    <gazebo reference="link2">
        <selfCollide>true</selfCollide>
    </gazebo>
    <gazebo reference="link3">
        <selfCollide>true</selfCollide>
    </gazebo>
    <gazebo reference="link4">
        <selfCollide>true</selfCollide>
    </gazebo>
    <gazebo reference="link5">
        <selfCollide>true</selfCollide>
    </gazebo>
    <joint name="gripper_fix" type="fixed">
        <parent link="link_eef" />
        <child link="Base_Gripper" />
        <origin rpy="0 0 0" xyz="0 0 0.003" />
    </joint>
    <link name="Base_Gripper">
        <inertial>
            <origin rpy="0 0 0" xyz="-0.0060074 0.00022945 0.055534" />
            <mass value="0.25675" />
            <inertia ixx="0.00029732" ixy="5.577E-07" ixz="6.8196E-06" iyy="0.0001154" iyz="-6.3991E-07" izz="0.00028425" />
        </inertial>
        <visual>
            <origin rpy="0 0 0" xyz="0 0 0" />
            <geometry>
                <mesh filename="package://robot_description/meshes/Gripper/Base.STL" />
            </geometry>
            <material name="">
                <color rgba="0.79216 0.81961 0.93333 1" />
            </material>
        </visual>
        <collision>
            <origin rpy="0 0 0" xyz="0 0 0" />
            <geometry>
                <mesh filename="package://robot_description/meshes/Gripper/Base.STL" />
            </geometry>
        </collision>
    </link>
    <link name="end_effector_link" />
    <joint name="end_effector_joint" type="fixed">
        <parent link="Base_Gripper" />
        <child link="end_effector_link" />
        <origin rpy="0 0 0" xyz="0 0 0.165" />
    </joint>
    <link name="Servo1">
        <inertial>
            <origin rpy="0 0 0" xyz="-4.50497350326651E-08 0.00440252858837619 0.0186297249994029" />
            <mass value="0.0250047254852256" />
            <inertia ixx="1.36408467918995E-05" ixy="1.57759886426113E-19" ixz="-1.71524171818996E-19" iyy="3.54946158391808E-06" iyz="-1.80956359903929E-06" izz="1.22463749616553E-05" />
        </inertial>
        <visual>
            <origin rpy="0 0 0" xyz="0 0 0" />
            <geometry>
                <mesh filename="package://robot_description/meshes/Gripper/Servo1.STL" />
            </geometry>
            <material name="">
                <color rgba="0.792156862745098 0.819607843137255 0.933333333333333 1" />
            </material>
        </visual>
        <collision>
            <origin rpy="0 0 0" xyz="0 0 0" />
            <geometry>
                <mesh filename="package://robot_description/meshes/Gripper/Servo1.STL" />
            </geometry>
        </collision>
    </link>
    <joint name="Rev1Servo" type="revolute">
        <origin rpy="0 -0.36888 -1.5708" xyz="0 0.035167 0.088595" />
        <parent link="Base_Gripper" />
        <child link="Servo1" />
        <axis xyz="0 1 0" />
        <limit effort="0" lower="-0.28" upper="0.40" velocity="0" />
    </joint>
    <link name="Dedo1">
        <inertial>
            <origin rpy="0 0 0" xyz="-0.0339572900023838 -9.3618305648923E-08 0.148246675379403" />
            <mass value="0.0622990489702351" />
            <inertia ixx="0.000123328183626577" ixy="-1.22881098411723E-10" ixz="-5.84361445598599E-06" iyy="0.000126724273269253" iyz="1.57270956526926E-10" izz="1.60489416583839E-05" />
        </inertial>
        <visual>
            <origin rpy="0 0 0" xyz="0 0 0" />
            <geometry>
                <mesh filename="package://robot_description/meshes/Gripper/Dedo1.STL" />
            </geometry>
            <material name="">
                <color rgba="0.792156862745098 0.819607843137255 0.933333333333333 1" />
            </material>
        </visual>
        <collision>
            <origin rpy="0 0 0" xyz="0 0 0" />
            <geometry>
                <mesh filename="package://robot_description/meshes/Gripper/Dedo1.STL" />
            </geometry>
        </collision>
    </link>
    <joint name="Fix1Dedo" type="fixed">
        <origin rpy="0 0 0" xyz="0.035 0.0021425 -0.0685" />
        <parent link="Servo1" />
        <child link="Dedo1" />
        <axis xyz="0 0 0" />
    </joint>
    <link name="Servo2">
        <inertial>
            <origin rpy="0 0 0" xyz="-4.50497350118484E-08 0.00440252858837639 0.0186297249994028" />
            <mass value="0.0250047254852253" />
            <inertia ixx="1.36408467918995E-05" ixy="1.66044927441445E-19" ixz="-1.7205356741103E-19" iyy="3.54946158391805E-06" iyz="-1.80956359903932E-06" izz="1.22463749616553E-05" />
        </inertial>
        <visual>
            <origin rpy="0 0 0" xyz="0 0 0" />
            <geometry>
                <mesh filename="package://robot_description/meshes/Gripper/Servo2.STL" />
            </geometry>
            <material name="">
                <color rgba="0.792156862745098 0.819607843137255 0.933333333333333 1" />
            </material>
        </visual>
        <collision>
            <origin rpy="0 0 0" xyz="0 0 0" />
            <geometry>
                <mesh filename="package://robot_description/meshes/Gripper/Servo2.STL" />
            </geometry>
        </collision>
    </link>
    <joint name="Rev2Servo" type="revolute">
        <origin rpy="0 -0.12482 -1.5708" xyz="0 -0.034832 0.088595" />
        <parent link="Base_Gripper" />
        <child link="Servo2" />
        <axis xyz="0 1 0" />
        <limit effort="0" lower="0.06" upper="0.75" velocity="0" />
    </joint>
    <link name="Dedo2">
        <inertial>
            <origin rpy="0 0 0" xyz="-0.0339571351919315 -9.20512037367108E-08 0.148247430105431" />
            <mass value="0.0622996947963828" />
            <inertia ixx="0.000123327640391479" ixy="-1.34548142614061E-10" ixz="-5.84362978685844E-06" iyy="0.000126723917872848" iyz="1.53337647171162E-10" izz="1.60491213480393E-05" />
        </inertial>
        <visual>
            <origin rpy="0 0 0" xyz="0 0 0" />
            <geometry>
                <mesh filename="package://robot_description/meshes/Gripper/Dedo2.STL" />
            </geometry>
            <material name="">
                <color rgba="0.792156862745098 0.819607843137255 0.933333333333333 1" />
            </material>
        </visual>
        <collision>
            <origin rpy="0 0 0" xyz="0 0 0" />
            <geometry>
                <mesh filename="package://robot_description/meshes/Gripper/Dedo2.STL" />
            </geometry>
        </collision>
    </link>
    <joint name="Fix2Dedo" type="fixed">
        <origin rpy="0 0 -3.1416" xyz="-0.035 0.0021425 -0.0685" />
        <parent link="Servo2" />
        <child link="Dedo2" />
        <axis xyz="0 0 0" />
    </joint>
    <transmission name="trans_odom_y">
        <type>transmission_interface/SimpleTransmission</type>
        <joint name="odom_y">
            <hardwareInterface>hardware_interface/EffortJointInterface</hardwareInterface>
        </joint>
        <actuator name="odom_y_motor">
            <hardwareInterface>hardware_interface/EffortJointInterface</hardwareInterface>
            <mechanicalReduction>1</mechanicalReduction>
        </actuator>
    </transmission>
    <transmission name="trans_odom_x">
        <type>transmission_interface/SimpleTransmission</type>
        <joint name="odom_x">
            <hardwareInterface>hardware_interface/EffortJointInterface</hardwareInterface>
        </joint>
        <actuator name="odom_x_motor">
            <hardwareInterface>hardware_interface/EffortJointInterface</hardwareInterface>
            <mechanicalReduction>1</mechanicalReduction>
        </actuator>
    </transmission>
    <transmission name="trans_odom_r">
        <type>transmission_interface/SimpleTransmission</type>
        <joint name="odom_r">
            <hardwareInterface>hardware_interface/EffortJointInterface</hardwareInterface>
        </joint>
        <actuator name="odom_r_motor">
            <hardwareInterface>hardware_interface/EffortJointInterface</hardwareInterface>
            <mechanicalReduction>1</mechanicalReduction>
        </actuator>
    </transmission>
    <transmission name="trans_Llanta1Cont">
        <type>transmission_interface/SimpleTransmission</type>
        <joint name="Llanta1Cont">
            <hardwareInterface>hardware_interface/EffortJointInterface</hardwareInterface>
        </joint>
        <actuator name="Llanta1Cont_motor">
            <hardwareInterface>hardware_interface/EffortJointInterface</hardwareInterface>
            <mechanicalReduction>1</mechanicalReduction>
        </actuator>
    </transmission>
    <transmission name="trans_Llanta2Cont">
        <type>transmission_interface/SimpleTransmission</type>
        <joint name="Llanta2Cont">
            <hardwareInterface>hardware_interface/EffortJointInterface</hardwareInterface>
        </joint>
        <actuator name="Llanta2Cont_motor">
            <hardwareInterface>hardware_interface/EffortJointInterface</hardwareInterface>
            <mechanicalReduction>1</mechanicalReduction>
        </actuator>
    </transmission>
    <transmission name="trans_Loca1Cont">
        <type>transmission_interface/SimpleTransmission</type>
        <joint name="Loca1Cont">
            <hardwareInterface>hardware_interface/EffortJointInterface</hardwareInterface>
        </joint>
        <actuator name="Loca1Cont_motor">
            <hardwareInterface>hardware_interface/EffortJointInterface</hardwareInterface>
            <mechanicalReduction>1</mechanicalReduction>
        </actuator>
    </transmission>
    <transmission name="trans_LlantaLoca1Cont">
        <type>transmission_interface/SimpleTransmission</type>
        <joint name="LlantaLoca1Cont">
            <hardwareInterface>hardware_interface/EffortJointInterface</hardwareInterface>
        </joint>
        <actuator name="LlantaLoca1Cont_motor">
            <hardwareInterface>hardware_interface/EffortJointInterface</hardwareInterface>
            <mechanicalReduction>1</mechanicalReduction>
        </actuator>
    </transmission>
    <transmission name="trans_Loca2Cont">
        <type>transmission_interface/SimpleTransmission</type>
        <joint name="Loca2Cont">
            <hardwareInterface>hardware_interface/EffortJointInterface</hardwareInterface>
        </joint>
        <actuator name="Loca2Cont_motor">
            <hardwareInterface>hardware_interface/EffortJointInterface</hardwareInterface>
            <mechanicalReduction>1</mechanicalReduction>
        </actuator>
    </transmission>
    <transmission name="trans_LlantaLoca2Cont">
        <type>transmission_interface/SimpleTransmission</type>
        <joint name="LlantaLoca2Cont">
            <hardwareInterface>hardware_interface/EffortJointInterface</hardwareInterface>
        </joint>
        <actuator name="LlantaLoca2Cont_motor">
            <hardwareInterface>hardware_interface/EffortJointInterface</hardwareInterface>
            <mechanicalReduction>1</mechanicalReduction>
        </actuator>
    </transmission>
    <transmission name="trans_Cam1Rev1">
        <type>transmission_interface/SimpleTransmission</type>
        <joint name="Cam1Rev1">
            <hardwareInterface>hardware_interface/EffortJointInterface</hardwareInterface>
        </joint>
        <actuator name="Cam1Rev1_motor">
            <hardwareInterface>hardware_interface/EffortJointInterface</hardwareInterface>
            <mechanicalReduction>1</mechanicalReduction>
        </actuator>
    </transmission>
    <transmission name="trans_Cam1Rev2">
        <type>transmission_interface/SimpleTransmission</type>
        <joint name="Cam1Rev2">
            <hardwareInterface>hardware_interface/EffortJointInterface</hardwareInterface>
        </joint>
        <actuator name="Cam1Rev2_motor">
            <hardwareInterface>hardware_interface/EffortJointInterface</hardwareInterface>
            <mechanicalReduction>1</mechanicalReduction>
        </actuator>
    </transmission>
    <transmission name="trans_Cam2Rev">
        <type>transmission_interface/SimpleTransmission</type>
        <joint name="Cam2Rev">
            <hardwareInterface>hardware_interface/EffortJointInterface</hardwareInterface>
        </joint>
        <actuator name="Cam2Rev_motor">
            <hardwareInterface>hardware_interface/EffortJointInterface</hardwareInterface>
            <mechanicalReduction>1</mechanicalReduction>
        </actuator>
    </transmission>
    <transmission name="trans_Rev1Servo">
        <type>transmission_interface/SimpleTransmission</type>
        <joint name="Rev1Servo">
            <hardwareInterface>hardware_interface/EffortJointInterface</hardwareInterface>
        </joint>
        <actuator name="Rev1Servo_motor">
            <hardwareInterface>hardware_interface/EffortJointInterface</hardwareInterface>
            <mechanicalReduction>1</mechanicalReduction>
        </actuator>
    </transmission>
    <transmission name="trans_Rev2Servo">
        <type>transmission_interface/SimpleTransmission</type>
        <joint name="Rev2Servo">
            <hardwareInterface>hardware_interface/EffortJointInterface</hardwareInterface>
        </joint>
        <actuator name="Rev2Servo_motor">
            <hardwareInterface>hardware_interface/EffortJointInterface</hardwareInterface>
            <mechanicalReduction>1</mechanicalReduction>
        </actuator>
    </transmission>
</robot>

