<?xml version="1.0" encoding="utf-8"?>
<!-- This URDF was automatically created by SolidWorks to URDF Exporter! Originally created by Stephen Brawner (brawner@gmail.com) 
     Commit Version: 1.6.0-4-g7f85cfe  Build Version: 1.6.7995.38578
     For more information, please see http://wiki.ros.org/sw_urdf_exporter -->
<robot xmlns:xacro="http://ros.org/wiki/xacro" name="Gripper">
  <xacro:macro name="load_gripperSF" params="attach_to:='' xyz:='0 0 0' rpy:='0 0 0'">
    <xacro:unless value="${attach_to == ''}">
      <joint name="gripper_fix" type="fixed">
        <parent link="${attach_to}"/>
        <child link="Base_Gripper"/>
        <origin xyz="${xyz}" rpy="${rpy}"/>
      </joint>
    </xacro:unless>

    <link name="end_effector_link">
    </link>
    <joint name="end_effector_joint" type="fixed">
        <parent link="Base_Gripper" />
        <child link="end_effector_link" />
        <origin xyz="0.0 -0.125 0" rpy="1.57 0 -1.57" />
    </joint>

    <link
      name="Base_Gripper">
      <inertial>
        <origin
          xyz="4.21738922031144E-18 2.00787620612413E-18 0.0378144840174591"
          rpy="0 0 0" />
        <mass
          value="0.516607789353608" />
        <inertia
          ixx="0.000831389945414142"
          ixy="-2.21787801740781E-20"
          ixz="1.66219465220325E-20"
          iyy="0.000443816179175048"
          iyz="3.05902948293233E-21"
          izz="0.000681097815743884" />
      </inertial>
      <visual>
        <origin
          xyz="0 0 0"
          rpy="1.57 0 0" />
        <geometry>
          <mesh
            filename="package://robot_description/meshes/GripperSF/Base_Gripper.STL" />
        </geometry>
        <material
          name="">
          <color
            rgba="0.792156862745098 0.819607843137255 0.933333333333333 1" />
        </material>
      </visual>
      <collision>
        <origin
          xyz="0 0 0"
          rpy="0 0 0" />
        <geometry>
          <mesh
            filename="package://robot_description/meshes/GripperSF/Base_Gripper.STL" />
        </geometry>
      </collision>
  </link>
  <link
    name="Servo1">
    <inertial>
      <origin
        xyz="2.08166817117217E-17 0.00765209400201583 0.002"
        rpy="0 0 0" />
      <mass
        value="0.00340320788790707" />
      <inertia
        ixx="3.64324463782157E-07"
        ixy="-7.27918939046664E-23"
        ixz="-2.27911008833175E-24"
        iyy="1.72972745084653E-07"
        iyz="3.50518784550926E-24"
        izz="5.28221987832391E-07" />
    </inertial>
    <visual>
      <origin
        xyz="0 0 0"
        rpy="0 0 0" />
      <geometry>
        <mesh
          filename="package://robot_description/meshes/GripperSF/Servo1.STL" />
      </geometry>
      <material
        name="">
        <color
          rgba="0.792156862745098 0.819607843137255 0.933333333333333 1" />
      </material>
    </visual>
    <collision>
      <origin
        xyz="0 0 0"
        rpy="0 0 0" />
      <geometry>
        <mesh
          filename="package://robot_description/meshes/GripperSF/Servo1.STL" />
      </geometry>
    </collision>
  </link>
  <joint
    name="Rev1Servo"
    type="revolute">
    <origin
      xyz="0.025 -0.085 0.0125"
      rpy="1.5708 -0.7854 1.5708" />
    <parent
      link="Base_Gripper" />
    <child
      link="Servo1" />
    <axis
      xyz="0 0 1" />
    <limit
      lower="-0.52"
      upper="0.52"
      effort="0"
      velocity="0" />
  </joint>
  <link
    name="Dedo1">
    <inertial>
      <origin
        xyz="0.025 0.0194950722582391 0.0215202503489297"
        rpy="0 0 0" />
      <mass
        value="0.0481456303681194" />
      <inertia
        ixx="1.85056890508066E-05"
        ixy="6.4090118340269E-22"
        ixz="1.49782108916524E-21"
        iyy="2.29959536609367E-05"
        iyz="-7.07475784630465E-06"
        izz="1.55704147099196E-05" />
    </inertial>
    <visual>
      <origin
        xyz="0 0 0"
        rpy="3.14 0 0" />
      <geometry>
        <mesh
          filename="package://robot_description/meshes/GripperSF/Dedo1.STL" />
      </geometry>
      <material
        name="">
        <color
          rgba="0.792156862745098 0.819607843137255 0.933333333333333 1" />
      </material>
    </visual>
    <collision>
      <origin
        xyz="0 0 0"
        rpy="0 0 0" />
      <geometry>
        <mesh
          filename="package://robot_description/meshes/GripperSF/Dedo1.STL" />
      </geometry>
    </collision>
  </link>
  <joint
    name="Fix1Dedo"
    type="fixed">
    <origin
      xyz="0 0.025 -0.046"
      rpy="3.1416 -1.5708 0" />
    <parent
      link="Servo1" />
    <child
      link="Dedo1" />
    <axis
      xyz="0 0 0" />
  </joint>
  <link
    name="Servo2">
    <inertial>
      <origin
        xyz="-6.93889390390723E-18 0.00765209400201584 0.00200000000000001"
        rpy="0 0 0" />
      <mass
        value="0.00340320788790707" />
      <inertia
        ixx="3.64324463782157E-07"
        ixy="1.45583787809333E-22"
        ixz="4.15267079728299E-24"
        iyy="1.72972745084653E-07"
        iyz="3.30065685426304E-24"
        izz="5.28221987832391E-07" />
    </inertial>
    <visual>
      <origin
        xyz="0 0 0"
        rpy="0 0 0" />
      <geometry>
        <mesh
          filename="package://robot_description/meshes/GripperSF/Servo2.STL" />
      </geometry>
      <material
        name="">
        <color
          rgba="0.792156862745098 0.819607843137255 0.933333333333333 1" />
      </material>
    </visual>
    <collision>
      <origin
        xyz="0 0 0"
        rpy="0 0 0" />
      <geometry>
        <mesh
          filename="package://robot_description/meshes/GripperSF/Servo2.STL" />
      </geometry>
    </collision>
  </link>
  <joint
    name="Rev2Servo"
    type="revolute">
    <origin
      xyz="0.025 -0.085 -0.0125"
      rpy="-1.5708 -0.7854 -1.5708" />
    <parent
      link="Base_Gripper" />
    <child
      link="Servo2" />
    <axis
      xyz="0 0 1" />
    <limit
      lower="-0.52"
      upper="0.52"
      effort="0"
      velocity="0" />
    <mimic
      joint="Rev1Servo"
      multiplier="-1"
      offset="0" />
  </joint>
  <link
    name="Dedo2">
    <inertial>
      <origin
        xyz="0.025 0.019495072258239 0.0215202503489296"
        rpy="0 0 0" />
      <mass
        value="0.0481456303681194" />
      <inertia
        ixx="1.85056890508066E-05"
        ixy="4.84183719412462E-21"
        ixz="3.67595393072787E-21"
        iyy="2.29959536609367E-05"
        iyz="-7.07475784630464E-06"
        izz="1.55704147099196E-05" />
    </inertial>
    <visual>
      <origin
        xyz="0 0 0"
        rpy="0 0 0" />
      <geometry>
        <mesh
          filename="package://robot_description/meshes/GripperSF/Dedo2.STL" />
      </geometry>
      <material
        name="">
        <color
          rgba="0.792156862745098 0.819607843137255 0.933333333333333 1" />
      </material>
    </visual>
    <collision>
      <origin
        xyz="0 0 0"
        rpy="0 0 0" />
      <geometry>
        <mesh
          filename="package://robot_description/meshes/GripperSF/Dedo2.STL" />
      </geometry>
    </collision>
  </link>
  <joint
    name="Fix2Dedo"
    type="fixed">
    <origin
      xyz="0 0.025 0.004"
      rpy="0 1.5708 0" />
    <parent
      link="Servo2" />
    <child
      link="Dedo2" />
    <axis
      xyz="0 0 0" />
  </joint>
  </xacro:macro>
</robot>